Workbook

Sheet Sheet1
A1: ciclo_original | B1: grupo_original | C1: cultivo_original | D1: area_sembrada_ha | E1: año | F1: fuente_taxonomia | G1: ciclo_armonizado | H1: grupo_armonizado | I1: cultivo_armonizado | J1: notas | K1: Armonizado | L1: porcentaje acumulado armonizado 2018 | M1: porcentaje acumulado armonizado 2019
A2: PERMANENTE | B2: OTROS PERMANENTES | C2: CAFE | D2: 10940392 | E2: 2007-2018 | F2: Eva antiguo | G2: Permanente | H2: Cultivos tropicales tradicionales | I2: Café | K2: TRUE | L2: =SUMIFS($D$2:$D2,$E$2:$E2,"2007-2018",$K$2:$K2,TRUE)/auxiliar!$B$3 -> 0.18132787 | M2: =SUMIFS($D$2:$D2,$E$2:$E2,"2019-2024",$K$2:$K2,TRUE)/auxiliar!$B$4 -> 0
A3: TRANSITORIO | B3: CEREALES | C3: MAIZ | D3: 7606746.7 | E3: 2007-2018 | F3: Eva antiguo | G3: Transitorio | H3: Cereales | I3: Maíz | K3: TRUE | L3: =SUMIFS($D$2:$D3,$E$2:$E3,"2007-2018",$K$2:$K3,TRUE)/auxiliar!$B$3 -> 0.30740335 | M3: =SUMIFS($D$2:$D3,$E$2:$E3,"2019-2024",$K$2:$K3,TRUE)/auxiliar!$B$4 -> 0
A4: TRANSITORIO | B4: CEREALES | C4: ARROZ | D4: 6822923 | E4: 2007-2018 | F4: Eva antiguo | G4: Transitorio | H4: Cereales | I4: Arroz | K4: TRUE | L4: =SUMIFS($D$2:$D4,$E$2:$E4,"2007-2018",$K$2:$K4,TRUE)/auxiliar!$B$3 -> 0.4204876 | M4: =SUMIFS($D$2:$D4,$E$2:$E4,"2019-2024",$K$2:$K4,TRUE)/auxiliar!$B$4 -> 0
A5: PERMANENTE | B5: OLEAGINOSAS | C5: PALMA DE ACEITE | D5: 6055813.5 | E5: 2007-2018 | F5: Eva antiguo | G5: Permanente | H5: Oleaginosas | I5: Palma de aceite | K5: TRUE | L5: =SUMIFS($D$2:$D5,$E$2:$E5,"2007-2018",$K$2:$K5,TRUE)/auxiliar!$B$3 -> 0.52085765 | M5: =SUMIFS($D$2:$D5,$E$2:$E5,"2019-2024",$K$2:$K5,TRUE)/auxiliar!$B$4 -> 0
A6: PERMANENTE | B6: TUBERCULOS Y PLATANOS | C6: PLATANO | D6: 5252053.5 | E6: 2007-2018 | F6: Eva antiguo | G6: Permanente | H6: Frutales | I6: Plátano | K6: TRUE | L6: =SUMIFS($D$2:$D6,$E$2:$E6,"2007-2018",$K$2:$K6,TRUE)/auxiliar!$B$3 -> 0.60790606 | M6: =SUMIFS($D$2:$D6,$E$2:$E6,"2019-2024",$K$2:$K6,TRUE)/auxiliar!$B$4 -> 0
A7: PERMANENTE | B7: OTROS PERMANENTES | C7: CAÑA PANELERA | D7: 2837352.5 | E7: 2007-2018 | F7: Eva antiguo | G7: Permanente | H7: Cultivos tropicales tradicionales | I7: Caña | J7: La suma de las cañas de 2018 coincide con el valor de Caña en 2019 | K7: TRUE | L7: =SUMIFS($D$2:$D7,$E$2:$E7,"2007-2018",$K$2:$K7,TRUE)/auxiliar!$B$3 -> 0.6549328 | M7: =SUMIFS($D$2:$D7,$E$2:$E7,"2019-2024",$K$2:$K7,TRUE)/auxiliar!$B$4 -> 0
A8: PERMANENTE | B8: OTROS PERMANENTES | C8: CAÑA AZUCARERA | D8: 2778985.7 | E8: 2007-2018 | F8: Eva antiguo | G8: Permanente | H8: Cultivos tropicales tradicionales | I8: Caña | J8: La suma de las cañas de 2018 coincide con el valor de Caña en 2019 | K8: TRUE | L8: =SUMIFS($D$2:$D8,$E$2:$E8,"2007-2018",$K$2:$K8,TRUE)/auxiliar!$B$3 -> 0.70099217 | M8: =SUMIFS($D$2:$D8,$E$2:$E8,"2019-2024",$K$2:$K8,TRUE)/auxiliar!$B$4 -> 0
A9: ANUAL | B9: TUBERCULOS Y PLATANOS | C9: YUCA | D9: 2583844.1 | E9: 2007-2018 | F9: Eva antiguo | G9: Transitorio | H9: Raíces y tubérculos | I9: Yuca | K9: TRUE | L9: =SUMIFS($D$2:$D9,$E$2:$E9,"2007-2018",$K$2:$K9,TRUE)/auxiliar!$B$3 -> 0.74381723 | M9: =SUMIFS($D$2:$D9,$E$2:$E9,"2019-2024",$K$2:$K9,TRUE)/auxiliar!$B$4 -> 0
A10: PERMANENTE | B10: OTROS PERMANENTES | C10: CACAO | D10: 2263985.4 | E10: 2007-2018 | F10: Eva antiguo | G10: Permanente | H10: Cultivos tropicales tradicionales | I10: Cacao | K10: TRUE | L10: =SUMIFS($D$2:$D10,$E$2:$E10,"2007-2018",$K$2:$K10,TRUE)/auxiliar!$B$3 -> 0.7813409 | M10: =SUMIFS($D$2:$D10,$E$2:$E10,"2019-2024",$K$2:$K10,TRUE)/auxiliar!$B$4 -> 0
A11: TRANSITORIO | B11: TUBERCULOS Y PLATANOS | C11: PAPA | D11: 2179556.2 | E11: 2007-2018 | F11: Eva antiguo | G11: Transitorio | H11: Raíces y tubérculos | I11: Papa | K11: TRUE | L11: =SUMIFS($D$2:$D11,$E$2:$E11,"2007-2018",$K$2:$K11,TRUE)/auxiliar!$B$3 -> 0.81746523 | M11: =SUMIFS($D$2:$D11,$E$2:$E11,"2019-2024",$K$2:$K11,TRUE)/auxiliar!$B$4 -> 0
A12: TRANSITORIO | B12: LEGUMINOSAS | C12: FRIJOL | D12: 1602215.8 | E12: 2007-2018 | F12: Eva antiguo | G12: Transitorio | H12: Leguminosas | I12: Frijol | K12: TRUE | L12: =SUMIFS($D$2:$D12,$E$2:$E12,"2007-2018",$K$2:$K12,TRUE)/auxiliar!$B$3 -> 0.84402062 | M12: =SUMIFS($D$2:$D12,$E$2:$E12,"2019-2024",$K$2:$K12,TRUE)/auxiliar!$B$4 -> 0
A13: PERMANENTE | B13: FRUTALES | C13: BANANO | D13: 966623.33 | E13: 2007-2018 | F13: Eva antiguo | G13: Permanente | H13: Frutales | I13: Banano | K13: TRUE | L13: =SUMIFS($D$2:$D13,$E$2:$E13,"2007-2018",$K$2:$K13,TRUE)/auxiliar!$B$3 -> 0.86004159 | M13: =SUMIFS($D$2:$D13,$E$2:$E13,"2019-2024",$K$2:$K13,TRUE)/auxiliar!$B$4 -> 0
A14: PERMANENTE | B14: FORESTALES | C14: CAUCHO | D14: 559378.82 | E14: 2007-2018 | F14: Eva antiguo | J14: Pendiente | K14: FALSE | L14: =SUMIFS($D$2:$D14,$E$2:$E14,"2007-2018",$K$2:$K14,TRUE)/auxiliar!$B$3 -> 0.86004159 | M14: =SUMIFS($D$2:$D14,$E$2:$E14,"2019-2024",$K$2:$K14,TRUE)/auxiliar!$B$4 -> 0
A15: PERMANENTE | B15: FRUTALES | C15: AGUACATE | D15: 547688.54 | E15: 2007-2018 | F15: Eva antiguo | G15: Permanente | H15: Frutales | I15: Aguacate | K15: TRUE | L15: =SUMIFS($D$2:$D15,$E$2:$E15,"2007-2018",$K$2:$K15,TRUE)/auxiliar!$B$3 -> 0.86911907 | M15: =SUMIFS($D$2:$D15,$E$2:$E15,"2019-2024",$K$2:$K15,TRUE)/auxiliar!$B$4 -> 0
A16: TRANSITORIO | B16: LEGUMINOSAS | C16: SOYA | D16: 488453.23 | E16: 2007-2018 | F16: Eva antiguo | G16: Transitorio | H16: Oleaginosas | I16: Soya | K16: TRUE | L16: =SUMIFS($D$2:$D16,$E$2:$E16,"2007-2018",$K$2:$K16,TRUE)/auxiliar!$B$3 -> 0.87721477 | M16: =SUMIFS($D$2:$D16,$E$2:$E16,"2019-2024",$K$2:$K16,TRUE)/auxiliar!$B$4 -> 0
A17: PERMANENTE | B17: FRUTALES | C17: CITRICOS | D17: 476095.92 | E17: 2007-2018 | F17: Eva antiguo | G17: Permanente | H17: Frutales | I17: Otros cítricos | K17: TRUE | L17: =SUMIFS($D$2:$D17,$E$2:$E17,"2007-2018",$K$2:$K17,TRUE)/auxiliar!$B$3 -> 0.88510567 | M17: =SUMIFS($D$2:$D17,$E$2:$E17,"2019-2024",$K$2:$K17,TRUE)/auxiliar!$B$4 -> 0
A18: ANUAL | B18: TUBERCULOS Y PLATANOS | C18: ÑAME | D18: 433858.98 | E18: 2007-2018 | F18: Eva antiguo | G18: Transitorio | H18: Raíces y tubérculos | I18: Ñame | K18: TRUE | L18: =SUMIFS($D$2:$D18,$E$2:$E18,"2007-2018",$K$2:$K18,TRUE)/auxiliar!$B$3 -> 0.89229652 | M18: =SUMIFS($D$2:$D18,$E$2:$E18,"2019-2024",$K$2:$K18,TRUE)/auxiliar!$B$4 -> 0
A19: TRANSITORIO | B19: FIBRAS | C19: ALGODON | D19: 408854.09 | E19: 2007-2018 | F19: Eva antiguo | G19: Transitorio | H19: Cultivos tropicales tradicionales | I19: Algodón | K19: TRUE | L19: =SUMIFS($D$2:$D19,$E$2:$E19,"2007-2018",$K$2:$K19,TRUE)/auxiliar!$B$3 -> 0.89907293 | M19: =SUMIFS($D$2:$D19,$E$2:$E19,"2019-2024",$K$2:$K19,TRUE)/auxiliar!$B$4 -> 0
A20: TRANSITORIO | B20: LEGUMINOSAS | C20: ARVEJA | D20: 379713.29 | E20: 2007-2018 | F20: Eva antiguo | G20: Transitorio | H20: Leguminosas | I20: Arveja | K20: TRUE | L20: =SUMIFS($D$2:$D20,$E$2:$E20,"2007-2018",$K$2:$K20,TRUE)/auxiliar!$B$3 -> 0.90536636 | M20: =SUMIFS($D$2:$D20,$E$2:$E20,"2019-2024",$K$2:$K20,TRUE)/auxiliar!$B$4 -> 0
A21: PERMANENTE | B21: FRUTALES | C21: MANGO | D21: 333890.96 | E21: 2007-2018 | F21: Eva antiguo | G21: Permanente | H21: Frutales | I21: Mango | K21: TRUE | L21: =SUMIFS($D$2:$D21,$E$2:$E21,"2007-2018",$K$2:$K21,TRUE)/auxiliar!$B$3 -> 0.91090033 | M21: =SUMIFS($D$2:$D21,$E$2:$E21,"2019-2024",$K$2:$K21,TRUE)/auxiliar!$B$4 -> 0
A22: PERMANENTE | B22: FRUTALES | C22: PIÑA | D22: 256438.65 | E22: 2007-2018 | F22: Eva antiguo | G22: Permanente | H22: Frutales | I22: Piña | K22: TRUE | L22: =SUMIFS($D$2:$D22,$E$2:$E22,"2007-2018",$K$2:$K22,TRUE)/auxiliar!$B$3 -> 0.91515058 | M22: =SUMIFS($D$2:$D22,$E$2:$E22,"2019-2024",$K$2:$K22,TRUE)/auxiliar!$B$4 -> 0
A23: PERMANENTE | B23: FRUTALES | C23: NARANJA | D23: 235595.24 | E23: 2007-2018 | F23: Eva antiguo | G23: Permanente | H23: Frutales | I23: Naranja | K23: TRUE | L23: =SUMIFS($D$2:$D23,$E$2:$E23,"2007-2018",$K$2:$K23,TRUE)/auxiliar!$B$3 -> 0.91905538 | M23: =SUMIFS($D$2:$D23,$E$2:$E23,"2019-2024",$K$2:$K23,TRUE)/auxiliar!$B$4 -> 0
A24: PERMANENTE | B24: FRUTALES | C24: COCO | D24: 235018.39 | E24: 2007-2018 | F24: Eva antiguo | G24: Permanente | H24: Frutales | I24: Coco | K24: TRUE | L24: =SUMIFS($D$2:$D24,$E$2:$E24,"2007-2018",$K$2:$K24,TRUE)/auxiliar!$B$3 -> 0.92295061 | M24: =SUMIFS($D$2:$D24,$E$2:$E24,"2019-2024",$K$2:$K24,TRUE)/auxiliar!$B$4 -> 0
A25: PERMANENTE | B25: FIBRAS | C25: FIQUE | D25: 225195.98 | E25: 2007-2018 | F25: Eva antiguo | G25: Permanente | H25: Cultivos tropicales tradicionales | I25: Fique | K25: TRUE | L25: =SUMIFS($D$2:$D25,$E$2:$E25,"2007-2018",$K$2:$K25,TRUE)/auxiliar!$B$3 -> 0.92668305 | M25: =SUMIFS($D$2:$D25,$E$2:$E25,"2019-2024",$K$2:$K25,TRUE)/auxiliar!$B$4 -> 0
A26: TRANSITORIO | B26: HORTALIZAS | C26: TOMATE | D26: 212164.98 | E26: 2007-2018 | F26: Eva antiguo | G26: Transitorio | H26: Hortalizas | I26: Tomate | K26: TRUE | L26: =SUMIFS($D$2:$D26,$E$2:$E26,"2007-2018",$K$2:$K26,TRUE)/auxiliar!$B$3 -> 0.93019951 | M26: =SUMIFS($D$2:$D26,$E$2:$E26,"2019-2024",$K$2:$K26,TRUE)/auxiliar!$B$4 -> 0
... A41: TRANSITORIO | B41: CEREALES | C41: TRIGO | D41: 91067.257 | E41: 2007-2018 | F41: Eva antiguo | G41: Transitorio | H41: Cereales | I41: Trigo | K41: TRUE | L41: =SUMIFS($D$2:$D41,$E$2:$E41,"2007-2018",$K$2:$K41,TRUE)/auxiliar!$B$3 -> 0.96194261 | M41: =SUMIFS($D$2:$D41,$E$2:$E41,"2019-2024",$K$2:$K41,TRUE)/auxiliar!$B$4 -> 0
A42: TRANSITORIO | B42: OTROS TRANSITORIOS | C42: TABACO RUBIO | D42: 90843.502 | E42: 2007-2018 | F42: Eva antiguo | G42: Transitorio | H42: Cultivos tropicales tradicionales | I42: Tabaco | J42: La suma de los Tabacos de 2018 es coherente con el Tabaco de 2019 | K42: TRUE | L42: =SUMIFS($D$2:$D42,$E$2:$E42,"2007-2018",$K$2:$K42,TRUE)/auxiliar!$B$3 -> 0.96344826 | M42: =SUMIFS($D$2:$D42,$E$2:$E42,"2019-2024",$K$2:$K42,TRUE)/auxiliar!$B$4 -> 0
A43: TRANSITORIO | B43: HORTALIZAS | C43: CEBOLLA DE RAMA | D43: 90500.938 | E43: 2007-2018 | F43: Eva antiguo | G43: Transitorio | H43: Hortalizas | I43: Cebolla de rama | K43: TRUE | L43: =SUMIFS($D$2:$D43,$E$2:$E43,"2007-2018",$K$2:$K43,TRUE)/auxiliar!$B$3 -> 0.96494824 | M43: =SUMIFS($D$2:$D43,$E$2:$E43,"2019-2024",$K$2:$K43,TRUE)/auxiliar!$B$4 -> 0
A44: TRANSITORIO | B44: LEGUMINOSAS | C44: HABICHUELA | D44: 87457.699 | E44: 2007-2018 | F44: Eva antiguo | G44: Transitorio | H44: Leguminosas | I44: Habichuela | K44: TRUE | L44: =SUMIFS($D$2:$D44,$E$2:$E44,"2007-2018",$K$2:$K44,TRUE)/auxiliar!$B$3 -> 0.96639778 | M44: =SUMIFS($D$2:$D44,$E$2:$E44,"2019-2024",$K$2:$K44,TRUE)/auxiliar!$B$4 -> 0
A45: PERMANENTE | B45: FRUTALES | C45: PAPAYA | D45: 77288.505 | E45: 2007-2018 | F45: Eva antiguo | G45: Permanente | H45: Frutales | I45: Papaya | K45: TRUE | L45: =SUMIFS($D$2:$D45,$E$2:$E45,"2007-2018",$K$2:$K45,TRUE)/auxiliar!$B$3 -> 0.96767877 | M45: =SUMIFS($D$2:$D45,$E$2:$E45,"2019-2024",$K$2:$K45,TRUE)/auxiliar!$B$4 -> 0
A46: PERMANENTE | B46: FRUTALES | C46: BANANITO | D46: 76137.7 | E46: 2007-2018 | F46: Eva antiguo | J46: Pendiente | K46: FALSE | L46: =SUMIFS($D$2:$D46,$E$2:$E46,"2007-2018",$K$2:$K46,TRUE)/auxiliar!$B$3 -> 0.96767877 | M46: =SUMIFS($D$2:$D46,$E$2:$E46,"2019-2024",$K$2:$K46,TRUE)/auxiliar!$B$4 -> 0
A47: PERMANENTE | B47: OTROS PERMANENTES | C47: CAÑA MIEL | D47: 67088.313 | E47: 2007-2018 | F47: Eva antiguo | G47: Permanente | H47: Cultivos tropicales tradicionales | I47: Caña | J47: La suma de las cañas de 2018 coincide con el valor de Caña en 2019 | K47: TRUE | L47: =SUMIFS($D$2:$D47,$E$2:$E47,"2007-2018",$K$2:$K47,TRUE)/auxiliar!$B$3 -> 0.96879071 | M47: =SUMIFS($D$2:$D47,$E$2:$E47,"2019-2024",$K$2:$K47,TRUE)/auxiliar!$B$4 -> 0
A48: PERMANENTE | B48: FRUTALES | C48: GRANADILLA | D48: 60939.771 | E48: 2007-2018 | F48: Eva antiguo | G48: Permanente | H48: Frutales | I48: Granadilla | K48: TRUE | L48: =SUMIFS($D$2:$D48,$E$2:$E48,"2007-2018",$K$2:$K48,TRUE)/auxiliar!$B$3 -> 0.96980073 | M48: =SUMIFS($D$2:$D48,$E$2:$E48,"2019-2024",$K$2:$K48,TRUE)/auxiliar!$B$4 -> 0
A49: TRANSITORIO | B49: FRUTALES | C49: MELON | D49: 54990.861 | E49: 2007-2018 | F49: Eva antiguo | G49: Transitorio | H49: Hortalizas | I49: Melón | K49: TRUE | L49: =SUMIFS($D$2:$D49,$E$2:$E49,"2007-2018",$K$2:$K49,TRUE)/auxiliar!$B$3 -> 0.97071216 | M49: =SUMIFS($D$2:$D49,$E$2:$E49,"2019-2024",$K$2:$K49,TRUE)/auxiliar!$B$4 -> 0
A50: TRANSITORIO | B50: HORTALIZAS | C50: HORTALIZAS VARIAS | D50: 53753.186 | E50: 2007-2018 | F50: Eva antiguo | G50: Transitorio | H50: Hortalizas | I50: Otras hortalizas | K50: TRUE | L50: =SUMIFS($D$2:$D50,$E$2:$E50,"2007-2018",$K$2:$K50,TRUE)/auxiliar!$B$3 -> 0.97160307 | M50: =SUMIFS($D$2:$D50,$E$2:$E50,"2019-2024",$K$2:$K50,TRUE)/auxiliar!$B$4 -> 0
A51: PERMANENTE | B51: FRUTALES | C51: GUANABANA | D51: 50122.98 | E51: 2007-2018 | F51: Eva antiguo | G51: Permanente | H51: Frutales | I51: Guanábana | K51: TRUE | L51: =SUMIFS($D$2:$D51,$E$2:$E51,"2007-2018",$K$2:$K51,TRUE)/auxiliar!$B$3 -> 0.97243382 | M51: =SUMIFS($D$2:$D51,$E$2:$E51,"2019-2024",$K$2:$K51,TRUE)/auxiliar!$B$4 -> 0
A52: TRANSITORIO | B52: OLEAGINOSAS | C52: AJONJOLI | D52: 49998.545 | E52: 2007-2018 | F52: Eva antiguo | G52: Transitorio | H52: Oleaginosas | I52: Ajonjolí | K52: TRUE | L52: =SUMIFS($D$2:$D52,$E$2:$E52,"2007-2018",$K$2:$K52,TRUE)/auxiliar!$B$3 -> 0.9732625 | M52: =SUMIFS($D$2:$D52,$E$2:$E52,"2019-2024",$K$2:$K52,TRUE)/auxiliar!$B$4 -> 0
A53: ANUAL | B53: OTROS PERMANENTES | C53: TABACO NEGRO | D53: 49563.882 | E53: 2007-2018 | F53: Eva antiguo | G53: Transitorio | H53: Cultivos tropicales tradicionales | I53: Tabaco | J53: La suma de los Tabacos de 2018 es coherente con el Tabaco de 2019 | K53: TRUE | L53: =SUMIFS($D$2:$D53,$E$2:$E53,"2007-2018",$K$2:$K53,TRUE)/auxiliar!$B$3 -> 0.97408398 | M53: =SUMIFS($D$2:$D53,$E$2:$E53,"2019-2024",$K$2:$K53,TRUE)/auxiliar!$B$4 -> 0
A54: ANUAL | B54: TUBERCULOS Y PLATANOS | C54: MALANGA | D54: 49236.51 | E54: 2007-2018 | F54: Eva antiguo | G54: Transitorio | H54: Raíces y tubérculos | I54: Malanga, achín, yota, papa china, bore | J54: Pendiente | K54: TRUE | L54: =SUMIFS($D$2:$D54,$E$2:$E54,"2007-2018",$K$2:$K54,TRUE)/auxiliar!$B$3 -> 0.97490004 | M54: =SUMIFS($D$2:$D54,$E$2:$E54,"2019-2024",$K$2:$K54,TRUE)/auxiliar!$B$4 -> 0
...

Sheet auxiliar
B2: Area sembrada
A3: 2007-2018 | B3: =SUMIF(Sheet1!$E:$E,$A3,Sheet1!$D:$D) -> 60334864
A4: 2019-2024 | B4: =SUMIF(Sheet1!$E:$E,$A4,Sheet1!$D:$D) -> 32491337
